Workbook
Name GroomName: '01 START HERE'!$H$14
Name BrideName: '01 START HERE'!$D$14
Name ContingencyPct: '01 START HERE'!$H$27
Name TotalBudget: '01 START HERE'!$D$27
Name WeddingDate: '01 START HERE'!$D$15

Sheet 01 START HERE
B2: SRI LANKAN WEDDING MASTER PLANNER
B3: One-day wedding | all amounts in Sri Lankan Rupees (LKR) | dates DD/MM/YYYY
B5: HOW TO USE THIS WORKBOOK
B6: 1. YELLOW cells are for you to type in. GREY cells calculate themselves - do not overwrite them.
B7: 2. Fill this sheet in first, then compare vendors on 05a, record the winners on 05 Vendors, then price it up on 03 Budget.
B8: 3. Open 02 Dashboard every time - it lists exactly what needs attention today.
B9: 4. Never type a vendor or a budget line twice. Pick it from the dropdown so the totals stay linked.
B10: 5. Sheets 14-21 are the wedding-day operating pack. Print them and hand them to your coordinator.
B13: THE COUPLE & THE DAY
B14: Bride's full name | D14: Methuli | F14: Groom's full name | H14: Udara
B15: Wedding date | D15: 46633 | F15: Day of the week | H15: =TEXT(WeddingDate,"dddd") -> Friday
B16: Days to go | D16: =WeddingDate-TODAY() -> 365 | F16: Wedding type | H16: Poruwa + Registration + Reception
B17: Poruwa / ceremony time | D17: 0.41666667 | F17: Reception start | H17: 0.375
B18: Registration (signing) time | D18: 0.39583333 | F18: Expected finish | H18: 0.66666667
B19: Venue (one venue for the whole day) | D19: [Hotel / banquet hall] | F19: Town / district | H19: [Town, District]
B20: Ceremony area | D20: Ballroom | F20: Reception area | H20: [Ballroom]
B21: Venue contact person | D21: [Name] | F21: Venue phone | H21: [07X XXX XXXX]
B22: Wedding theme | D22: [e.g. Classic Kandyan] | F22: Colour palette | H22: [e.g. Ivory / Gold / Maroon]
B23: Main coordinator | D23: [Name] | F23: Coordinator phone | H23: [07X XXX XXXX]
B24: Emergency contact (day-of) | D24: [Name] | F24: Emergency phone | H24: [07X XXX XXXX]
B26: MONEY
B27: TOTAL WEDDING BUDGET (LKR) | D27: 4000000 | F27: Contingency reserve % | H27: 0.01
B28: Guests invited (pax) | D28: =SUM('09 Guests'!K7:K300) -> 156 | F28: Guests confirmed (pax) | H28: =SUM('09 Guests'!Y7:Y300) -> 0
B29: Indicative budget - replace with your own figures
B30: Budgeted (originally planned) | D30: =SUM('03 Budget'!E7:E300) -> 7318000 | F30: Quoted by vendors | H30: =SUM('03 Budget'!I7:I300) -> 896000
B31: Negotiated / agreed | D31: =SUM('03 Budget'!J7:J300) -> 0 | F31: Actual invoiced | H31: =SUM('03 Budget'!K7:K300) -> 896000
B32: FORECAST FINAL COST | D32: =SUM('03 Budget'!L7:L300) -> 4702500 | F32: Paid to date | H32: =SUM('03 Budget'!M7:M300) -> 896000
B33: Outstanding still to pay | D33: =SUM('03 Budget'!N7:N300) -> 3806500 | F33: Refundable deposits out | H33: =SUM('03 Budget'!O7:O300) -> 0
B34: Remaining against budget | D34: =TotalBudget-SUM('03 Budget'!L7:L300) -> -702500 | F34: Budget utilisation | H34: =IFERROR(SUM('03 Budget'!L7:L300)/TotalBudget,0) -> 1.175625
B36: WHERE THE MONEY COMES FROM
B37: Family & couple contributions agreed | D37: =SUM('06 Contributions'!G7:G60) -> 0 | F37: Contributions received | H37: =SUM('06 Contributions'!H7:H60) -> 0
B38: Expected cash gifts from guests | D38: =SUMIFS('09 Guests'!AE7:AE300,'09 Guests'!U7:U300,"<>Declined") -> 605000 | F38: Cash gifts received | H38: =SUM('09 Guests'!AF7:AF300) -> 0
B39: NET COST AFTER GIFTS & CONTRIBUTIONS | D39: =D32-D37-D38 -> 4097500 | F39: Shortfall still to fund | H39: =MAX(0,D39-H37-H38) -> 4097500
B41: ASSUMPTIONS YOU SHOULD CHECK
B42: - Wedding date 03/09/2027 (a Friday) was supplied by you. No homecoming event - this is a one-day wedding.
B43: - Poruwa, marriage registration and Kandyan dancers/drummers are pre-set as REQUIRED. Church/temple service is Optional.
B44: - ASSUMPTION: all 84 guest groups carried over from your old sheet are marked GROOM'S side. Change column F on 09 Guests where that is wrong.
B45: - ASSUMPTION: budget amounts are indicative market estimates for a c.200-guest hotel wedding, not quotes. Replace with your own figures.
B46: - Items marked VERIFY on 13 Ceremony & Legal must be confirmed with your Divisional Secretariat / Registrar - rules vary by district and religion.

Sheet 02 Dashboard
B2: MASTER DASHBOARD
B3: Everything on this sheet calculates itself. Read the ATTENTION REQUIRED panel at the bottom every time you open the workbook.
B4: AT A GLANCE
C5: DAYS TO GO | F5: TOTAL BUDGET | I5: FORECAST FINAL COST | L5: PAID SO FAR | O5: STILL TO PAY | R5: LEFT IN BUDGET
C6: =WeddingDate-TODAY() -> 365 | F6: =TotalBudget -> 4000000 | I6: =SUM('03 Budget'!L7:L300) -> 4702500 | L6: =SUM('03 Budget'!M7:M300) -> 896000 | O6: =SUM('03 Budget'!N7:N300) -> 3806500 | R6: =TotalBudget-SUM('03 Budget'!L7:L300) -> -702500
C8: GUESTS INVITED | F8: GUESTS CONFIRMED | I8: RSVP RESPONSE RATE | L8: TASKS COMPLETE | O8: VENDORS CONFIRMED | R8: NET COST AFTER GIFTS
C9: =SUM('09 Guests'!K7:K300) -> 156 | F9: =SUM('09 Guests'!Y7:Y300) -> 0 | I9: =IFERROR((COUNTIF('09 Guests'!U7:U300,"Accepted")+COUNTIF('09 Guests'!U7:U300,"Declined"))/COUNTA('09 Guests'!D7:D300),0) -> 0 | L9: =IFERROR(COUNTIF('07 Tasks'!K7:K250,"Completed")/COUNTA('07 Tasks'!D7:D250),0) -> 0.010752688 | O9: =IFERROR((COUNTIF('05 Vendors'!S7:S200,"Confirmed")+COUNTIF('05 Vendors'!S7:S200,"Completed"))/COUNTA('05 Vendors'!D7:D200),0) -> 0.16666667 | R9: =SUM('03 Budget'!L7:L300)-SUM('06 Contributions'!G7:G60)-SUMIFS('09 Guests'!AE7:AE300,'09 Guests'!U7:U300,"<>Declined") -> 4097500
B11: WHERE THE MONEY IS GOING
B12: Category | C12: Budgeted | E12: Forecast | G12: Paid | I12: Outstanding | K12: Variance
B13: VENUE & HOTEL | C13: =SUMIFS('03 Budget'!$E$7:$E$300,'03 Budget'!$C$7:$C$300,$B13) -> 624000 | E13: =SUMIFS('03 Budget'!$L$7:$L$300,'03 Budget'!$C$7:$C$300,$B13) -> 524000 | G13: =SUMIFS('03 Budget'!$M$7:$M$300,'03 Budget'!$C$7:$C$300,$B13) -> 0 | I13: =SUMIFS('03 Budget'!$N$7:$N$300,'03 Budget'!$C$7:$C$300,$B13) -> 524000 | K13: =SUMIFS('03 Budget'!$P$7:$P$300,'03 Budget'!$C$7:$C$300,$B13) -> -100000
B14: FOOD & BEVERAGE | C14: =SUMIFS('03 Budget'!$E$7:$E$300,'03 Budget'!$C$7:$C$300,$B14) -> 2280000 | E14: =SUMIFS('03 Budget'!$L$7:$L$300,'03 Budget'!$C$7:$C$300,$B14) -> 2007000 | G14: =SUMIFS('03 Budget'!$M$7:$M$300,'03 Budget'!$C$7:$C$300,$B14) -> 0 | I14: =SUMIFS('03 Budget'!$N$7:$N$300,'03 Budget'!$C$7:$C$300,$B14) -> 2007000 | K14: =SUMIFS('03 Budget'!$P$7:$P$300,'03 Budget'!$C$7:$C$300,$B14) -> -273000
B15: CAKE | C15: =SUMIFS('03 Budget'!$E$7:$E$300,'03 Budget'!$C$7:$C$300,$B15) -> 135000 | E15: =SUMIFS('03 Budget'!$L$7:$L$300,'03 Budget'!$C$7:$C$300,$B15) -> 120000 | G15: =SUMIFS('03 Budget'!$M$7:$M$300,'03 Budget'!$C$7:$C$300,$B15) -> 0 | I15: =SUMIFS('03 Budget'!$N$7:$N$300,'03 Budget'!$C$7:$C$300,$B15) -> 120000 | K15: =SUMIFS('03 Budget'!$P$7:$P$300,'03 Budget'!$C$7:$C$300,$B15) -> -15000
B16: PHOTOGRAPHY | C16: =SUMIFS('03 Budget'!$E$7:$E$300,'03 Budget'!$C$7:$C$300,$B16) -> 350000 | E16: =SUMIFS('03 Budget'!$L$7:$L$300,'03 Budget'!$C$7:$C$300,$B16) -> 180000 | G16: =SUMIFS('03 Budget'!$M$7:$M$300,'03 Budget'!$C$7:$C$300,$B16) -> 0 | I16: =SUMIFS('03 Budget'!$N$7:$N$300,'03 Budget'!$C$7:$C$300,$B16) -> 180000 | K16: =SUMIFS('03 Budget'!$P$7:$P$300,'03 Budget'!$C$7:$C$300,$B16) -> -170000
B17: VIDEOGRAPHY | C17: =SUMIFS('03 Budget'!$E$7:$E$300,'03 Budget'!$C$7:$C$300,$B17) -> 345000 | E17: =SUMIFS('03 Budget'!$L$7:$L$300,'03 Budget'!$C$7:$C$300,$B17) -> 35000 | G17: =SUMIFS('03 Budget'!$M$7:$M$300,'03 Budget'!$C$7:$C$300,$B17) -> 0 | I17: =SUMIFS('03 Budget'!$N$7:$N$300,'03 Budget'!$C$7:$C$300,$B17) -> 35000 | K17: =SUMIFS('03 Budget'!$P$7:$P$300,'03 Budget'!$C$7:$C$300,$B17) -> -310000
B18: BRIDE - ATTIRE & BEAUTY | C18: =SUMIFS('03 Budget'!$E$7:$E$300,'03 Budget'!$C$7:$C$300,$B18) -> 298000 | E18: =SUMIFS('03 Budget'!$L$7:$L$300,'03 Budget'!$C$7:$C$300,$B18) -> 271000 | G18: =SUMIFS('03 Budget'!$M$7:$M$300,'03 Budget'!$C$7:$C$300,$B18) -> 0 | I18: =SUMIFS('03 Budget'!$N$7:$N$300,'03 Budget'!$C$7:$C$300,$B18) -> 271000 | K18: =SUMIFS('03 Budget'!$P$7:$P$300,'03 Budget'!$C$7:$C$300,$B18) -> -27000
B19: GROOM - ATTIRE & GROOMING | C19: =SUMIFS('03 Budget'!$E$7:$E$300,'03 Budget'!$C$7:$C$300,$B19) -> 46000 | E19: =SUMIFS('03 Budget'!$L$7:$L$300,'03 Budget'!$C$7:$C$300,$B19) -> 46000 | G19: =SUMIFS('03 Budget'!$M$7:$M$300,'03 Budget'!$C$7:$C$300,$B19) -> 0 | I19: =SUMIFS('03 Budget'!$N$7:$N$300,'03 Budget'!$C$7:$C$300,$B19) -> 46000 | K19: =SUMIFS('03 Budget'!$P$7:$P$300,'03 Budget'!$C$7:$C$300,$B19) -> 0
B20: JEWELLERY | C20: =SUMIFS('03 Budget'!$E$7:$E$300,'03 Budget'!$C$7:$C$300,$B20) -> 905500 | E20: =SUMIFS('03 Budget'!$L$7:$L$300,'03 Budget'!$C$7:$C$300,$B20) -> 896000 | G20: =SUMIFS('03 Budget'!$M$7:$M$300,'03 Budget'!$C$7:$C$300,$B20) -> 896000 | I20: =SUMIFS('03 Budget'!$N$7:$N$300,'03 Budget'!$C$7:$C$300,$B20) -> 0 | K20: =SUMIFS('03 Budget'!$P$7:$P$300,'03 Budget'!$C$7:$C$300,$B20) -> -9500
B21: BRIDAL PARTY | C21: =SUMIFS('03 Budget'!$E$7:$E$300,'03 Budget'!$C$7:$C$300,$B21) -> 122000 | E21: =SUMIFS('03 Budget'!$L$7:$L$300,'03 Budget'!$C$7:$C$300,$B21) -> 67000 | G21: =SUMIFS('03 Budget'!$M$7:$M$300,'03 Budget'!$C$7:$C$300,$B21) -> 0 | I21: =SUMIFS('03 Budget'!$N$7:$N$300,'03 Budget'!$C$7:$C$300,$B21) -> 67000 | K21: =SUMIFS('03 Budget'!$P$7:$P$300,'03 Budget'!$C$7:$C$300,$B21) -> -55000
B22: DECOR & FLORALS | C22: =SUMIFS('03 Budget'!$E$7:$E$300,'03 Budget'!$C$7:$C$300,$B22) -> 676000 | E22: =SUMIFS('03 Budget'!$L$7:$L$300,'03 Budget'!$C$7:$C$300,$B22) -> 6000 | G22: =SUMIFS('03 Budget'!$M$7:$M$300,'03 Budget'!$C$7:$C$300,$B22) -> 0 | I22: =SUMIFS('03 Budget'!$N$7:$N$300,'03 Budget'!$C$7:$C$300,$B22) -> 6000 | K22: =SUMIFS('03 Budget'!$P$7:$P$300,'03 Budget'!$C$7:$C$300,$B22) -> -670000
B23: LIGHTING, SOUND & AV | C23: =SUMIFS('03 Budget'!$E$7:$E$300,'03 Budget'!$C$7:$C$300,$B23) -> 180000 | E23: =SUMIFS('03 Budget'!$L$7:$L$300,'03 Budget'!$C$7:$C$300,$B23) -> 0 | G23: =SUMIFS('03 Budget'!$M$7:$M$300,'03 Budget'!$C$7:$C$300,$B23) -> 0 | I23: =SUMIFS('03 Budget'!$N$7:$N$300,'03 Budget'!$C$7:$C$300,$B23) -> 0 | K23: =SUMIFS('03 Budget'!$P$7:$P$300,'03 Budget'!$C$7:$C$300,$B23) -> -180000
B24: ENTERTAINMENT | C24: =SUMIFS('03 Budget'!$E$7:$E$300,'03 Budget'!$C$7:$C$300,$B24) -> 375000 | E24: =SUMIFS('03 Budget'!$L$7:$L$300,'03 Budget'!$C$7:$C$300,$B24) -> 240000 | G24: =SUMIFS('03 Budget'!$M$7:$M$300,'03 Budget'!$C$7:$C$300,$B24) -> 0 | I24: =SUMIFS('03 Budget'!$N$7:$N$300,'03 Budget'!$C$7:$C$300,$B24) -> 240000 | K24: =SUMIFS('03 Budget'!$P$7:$P$300,'03 Budget'!$C$7:$C$300,$B24) -> -135000
... B32: MISCELLANEOUS | C32: =SUMIFS('03 Budget'!$E$7:$E$300,'03 Budget'!$C$7:$C$300,$B32) -> 233000 | E32: =SUMIFS('03 Budget'!$L$7:$L$300,'03 Budget'!$C$7:$C$300,$B32) -> 125000 | G32: =SUMIFS('03 Budget'!$M$7:$M$300,'03 Budget'!$C$7:$C$300,$B32) -> 0 | I32: =SUMIFS('03 Budget'!$N$7:$N$300,'03 Budget'!$C$7:$C$300,$B32) -> 125000 | K32: =SUMIFS('03 Budget'!$P$7:$P$300,'03 Budget'!$C$7:$C$300,$B32) -> -108000
B33: TOTAL | C33: =SUM(C13:C32) -> 7318000 | E33: =SUM(E13:E32) -> 4702500 | G33: =SUM(G13:G32) -> 896000 | I33: =SUM(I13:I32) -> 3806500 | K33: =SUM(K13:K32) -> -2615500
B36: WEDDING READINESS - based on completed tasks in 07 Tasks
B37: Area | C37: Done | E37: Total tasks | G37: Complete | I37: Progress
B38: Venue | C38: =COUNTIFS('07 Tasks'!$C$7:$C$250,$B38,'07 Tasks'!$K$7:$K$250,"Completed") -> 0 | E38: =COUNTIF('07 Tasks'!$C$7:$C$250,$B38) -> 4 | G38: =IFERROR($C38/$E38,0) -> 0 | I38: =IFERROR($C38/$E38,0) -> 0
B39: Food & Beverage | C39: =COUNTIFS('07 Tasks'!$C$7:$C$250,$B39,'07 Tasks'!$K$7:$K$250,"Completed") -> 0 | E39: =COUNTIF('07 Tasks'!$C$7:$C$250,$B39) -> 2 | G39: =IFERROR($C39/$E39,0) -> 0 | I39: =IFERROR($C39/$E39,0) -> 0
B40: Cake | C40: =COUNTIFS('07 Tasks'!$C$7:$C$250,$B40,'07 Tasks'!$K$7:$K$250,"Completed") -> 0 | E40: =COUNTIF('07 Tasks'!$C$7:$C$250,$B40) -> 1 | G40: =IFERROR($C40/$E40,0) -> 0 | I40: =IFERROR($C40/$E40,0) -> 0
B41: Decor & Florals | C41: =COUNTIFS('07 Tasks'!$C$7:$C$250,$B41,'07 Tasks'!$K$7:$K$250,"Completed") -> 0 | E41: =COUNTIF('07 Tasks'!$C$7:$C$250,$B41) -> 4 | G41: =IFERROR($C41/$E41,0) -> 0 | I41: =IFERROR($C41/$E41,0) -> 0
B42: Photography | C42: =COUNTIFS('07 Tasks'!$C$7:$C$250,$B42,'07 Tasks'!$K$7:$K$250,"Completed") -> 0 | E42: =COUNTIF('07 Tasks'!$C$7:$C$250,$B42) -> 6 | G42: =IFERROR($C42/$E42,0) -> 0 | I42: =IFERROR($C42/$E42,0) -> 0
B43: Videography | C43: =COUNTIFS('07 Tasks'!$C$7:$C$250,$B43,'07 Tasks'!$K$7:$K$250,"Completed") -> 0 | E43: =COUNTIF('07 Tasks'!$C$7:$C$250,$B43) -> 2 | G43: =IFERROR($C43/$E43,0) -> 0 | I43: =IFERROR($C43/$E43,0) -> 0
B44: Attire | C44: =COUNTIFS('07 Tasks'!$C$7:$C$250,$B44,'07 Tasks'!$K$7:$K$250,"Completed") -> 0 | E44: =COUNTIF('07 Tasks'!$C$7:$C$250,$B44) -> 8 | G44: =IFERROR($C44/$E44,0) -> 0 | I44: =IFERROR($C44/$E44,0) -> 0
B45: Jewellery | C45: =COUNTIFS('07 Tasks'!$C$7:$C$250,$B45,'07 Tasks'!$K$7:$K$250,"Completed") -> 1 | E45: =COUNTIF('07 Tasks'!$C$7:$C$250,$B45) -> 5 | G45: =IFERROR($C45/$E45,0) -> 0.2 | I45: =IFERROR($C45/$E45,0) -> 0.2
B46: Beauty & Grooming | C46: =COUNTIFS('07 Tasks'!$C$7:$C$250,$B46,'07 Tasks'!$K$7:$K$250,"Completed") -> 0 | E46: =COUNTIF('07 Tasks'!$C$7:$C$250,$B46) -> 7 | G46: =IFERROR($C46/$E46,0) -> 0 | I46: =IFERROR($C46/$E46,0) -> 0
B47: Invitations | C47: =COUNTIFS('07 Tasks'!$C$7:$C$250,$B47,'07 Tasks'!$K$7:$K$250,"Completed") -> 0 | E47: =COUNTIF('07 Tasks'!$C$7:$C$250,$B47) -> 5 | G47: =IFERROR($C47/$E47,0) -> 0 | I47: =IFERROR($C47/$E47,0) -> 0
B48: Guests & RSVP | C48: =COUNTIFS('07 Tasks'!$C$7:$C$250,$B48,'07 Tasks'!$K$7:$K$250,"Completed") -> 0 | E48: =COUNTIF('07 Tasks'!$C$7:$C$250,$B48) -> 8 | G48: =IFERROR($C48/$E48,0) -> 0 | I48: =IFERROR($C48/$E48,0) -> 0
B49: Transport | C49: =COUNTIFS('07 Tasks'!$C$7:$C$250,$B49,'07 Tasks'!$K$7:$K$250,"Completed") -> 0 | E49: =COUNTIF('07 Tasks'!$C$7:$C$250,$B49) -> 2 | G49: =IFERROR($C49/$E49,0) -> 0 | I49: =IFERROR($C49/$E49,0) -> 0
... B57: Logistics | C57: =COUNTIFS('07 Tasks'!$C$7:$C$250,$B57,'07 Tasks'!$K$7:$K$250,"Completed") -> 0 | E57: =COUNTIF('07 Tasks'!$C$7:$C$250,$B57) -> 9 | G57: =IFERROR($C57/$E57,0) -> 0 | I57: =IFERROR($C57/$E57,0) -> 0
B60: ATTENTION REQUIRED - read this every time you open the workbook
B61: Count | C61: Severity | F61: What needs your attention
...

Sheet 03 Budget
B2: MASTER BUDGET
B3: Budgeted -> Quoted -> Negotiated -> Actual. FORECAST automatically uses the most advanced number you have entered. PAID is pulled from 04 Payments - never type it.
D5: TOTALS | E5: =SUM(E7:E300) -> 7318000 | I5: =SUM(I7:I300) -> 896000 | J5: =SUM(J7:J300) -> 0 | K5: =SUM(K7:K300) -> 896000 | L5: =SUM(L7:L300) -> 4702500 | M5: =SUM(M7:M300) -> 896000 | N5: =SUM(N7:N300) -> 3806500 | O5: =SUM(O7:O300) -> 0 | P5: =SUM(P7:P300) -> -2615500
B6: ID | C6: Category | D6: Line item | E6: Budgeted | F6: Applies? | G6: Who pays | H6: Vendor | I6: Quoted | J6: Negotiated | K6: Actual | L6: FORECAST | M6: Paid | N6: Outstanding | O6: Refundable deposit | P6: Variance vs budget | Q6: Status | R6: Notes
B7: BG001 | C7: VENUE & HOTEL | D7: Venue hire - ceremony & reception hall | E7: 0 | F7: Not Applicable | L7: =IF($F7="Not Applicable",0,IF(K7>0,K7,IF(J7>0,J7,IF(I7>0,I7,E7)))) -> 0 | M7: =SUMIFS('04 Payments'!$K$7:$K$400,'04 Payments'!$D$7:$D$400,$B7) -> 0 | N7: =MAX(0,L7-M7) -> 0 | P7: =L7-E7 -> 0 | Q7: Not Started
B8: BG002 | C8: VENUE & HOTEL | D8: Garden / outdoor area | E8: 0 | F8: Not Applicable | L8: =IF($F8="Not Applicable",0,IF(K8>0,K8,IF(J8>0,J8,IF(I8>0,I8,E8)))) -> 0 | M8: =SUMIFS('04 Payments'!$K$7:$K$400,'04 Payments'!$D$7:$D$400,$B8) -> 0 | N8: =MAX(0,L8-M8) -> 0 | P8: =L8-E8 -> 0 | Q8: Not Started
B9: BG003 | C9: VENUE & HOTEL | D9: Bridal suite (wedding night) | E9: 10000 | F9: Required | G9: Groom | L9: =IF($F9="Not Applicable",0,IF(K9>0,K9,IF(J9>0,J9,IF(I9>0,I9,E9)))) -> 10000 | M9: =SUMIFS('04 Payments'!$K$7:$K$400,'04 Payments'!$D$7:$D$400,$B9) -> 0 | N9: =MAX(0,L9-M9) -> 10000 | P9: =L9-E9 -> 0 | Q9: Not Started
B10: BG004 | C10: VENUE & HOTEL | D10: Groom's getting-ready room | E10: 10000 | F10: Required | G10: Groom | L10: =IF($F10="Not Applicable",0,IF(K10>0,K10,IF(J10>0,J10,IF(I10>0,I10,E10)))) -> 10000 | M10: =SUMIFS('04 Payments'!$K$7:$K$400,'04 Payments'!$D$7:$D$400,$B10) -> 0 | N10: =MAX(0,L10-M10) -> 10000 | P10: =L10-E10 -> 0 | Q10: Not Started
B11: BG005 | C11: VENUE & HOTEL | D11: Service charge (10%) | E11: 180000 | F11: Required | G11: Groom | L11: =IF($F11="Not Applicable",0,IF(K11>0,K11,IF(J11>0,J11,IF(I11>0,I11,E11)))) -> 180000 | M11: =SUMIFS('04 Payments'!$K$7:$K$400,'04 Payments'!$D$7:$D$400,$B11) -> 0 | N11: =MAX(0,L11-M11) -> 180000 | P11: =L11-E11 -> 0 | Q11: Not Started
B12: BG006 | C12: VENUE & HOTEL | D12: Government taxes (VAT / SSCL / TDL) (18%) | E12: 324000 | F12: Required | G12: Groom | L12: =IF($F12="Not Applicable",0,IF(K12>0,K12,IF(J12>0,J12,IF(I12>0,I12,E12)))) -> 324000 | M12: =SUMIFS('04 Payments'!$K$7:$K$400,'04 Payments'!$D$7:$D$400,$B12) -> 0 | N12: =MAX(0,L12-M12) -> 324000 | P12: =L12-E12 -> 0 | Q12: Not Started
B13: BG007 | C13: VENUE & HOTEL | D13: Corkage | E13: 0 | F13: Not Applicable | L13: =IF($F13="Not Applicable",0,IF(K13>0,K13,IF(J13>0,J13,IF(I13>0,I13,E13)))) -> 0 | M13: =SUMIFS('04 Payments'!$K$7:$K$400,'04 Payments'!$D$7:$D$400,$B13) -> 0 | N13: =MAX(0,L13-M13) -> 0 | P13: =L13-E13 -> 0 | Q13: Not Started
B14: BG008 | C14: VENUE & HOTEL | D14: Overtime / extra hours | E14: 40000 | F14: Not Applicable | L14: =IF($F14="Not Applicable",0,IF(K14>0,K14,IF(J14>0,J14,IF(I14>0,I14,E14)))) -> 0 | M14: =SUMIFS('04 Payments'!$K$7:$K$400,'04 Payments'!$D$7:$D$400,$B14) -> 0 | N14: =MAX(0,L14-M14) -> 0 | P14: =L14-E14 -> -40000 | Q14: Not Started
B15: BG009 | C15: VENUE & HOTEL | D15: Generator / power backup | E15: 25000 | F15: Not Applicable | L15: =IF($F15="Not Applicable",0,IF(K15>0,K15,IF(J15>0,J15,IF(I15>0,I15,E15)))) -> 0 | M15: =SUMIFS('04 Payments'!$K$7:$K$400,'04 Payments'!$D$7:$D$400,$B15) -> 0 | N15: =MAX(0,L15-M15) -> 0 | P15: =L15-E15 -> -25000 | Q15: Not Started
B16: BG010 | C16: VENUE & HOTEL | D16: Parking | E16: 0 | F16: Not Applicable | L16: =IF($F16="Not Applicable",0,IF(K16>0,K16,IF(J16>0,J16,IF(I16>0,I16,E16)))) -> 0 | M16: =SUMIFS('04 Payments'!$K$7:$K$400,'04 Payments'!$D$7:$D$400,$B16) -> 0 | N16: =MAX(0,L16-M16) -> 0 | P16: =L16-E16 -> 0 | Q16: Not Started
B17: BG011 | C17: VENUE & HOTEL | D17: Security | E17: 15000 | F17: Not Applicable | L17: =IF($F17="Not Applicable",0,IF(K17>0,K17,IF(J17>0,J17,IF(I17>0,I17,E17)))) -> 0 | M17: =SUMIFS('04 Payments'!$K$7:$K$400,'04 Payments'!$D$7:$D$400,$B17) -> 0 | N17: =MAX(0,L17-M17) -> 0 | P17: =L17-E17 -> -15000 | Q17: Not Started
B18: BG012 | C18: VENUE & HOTEL | D18: Cleaning | E18: 0 | F18: Not Applicable | L18: =IF($F18="Not Applicable",0,IF(K18>0,K18,IF(J18>0,J18,IF(I18>0,I18,E18)))) -> 0 | M18: =SUMIFS('04 Payments'!$K$7:$K$400,'04 Payments'!$D$7:$D$400,$B18) -> 0 | N18: =MAX(0,L18-M18) -> 0 | P18: =L18-E18 -> 0 | Q18: Not Started
B19: BG013 | C19: VENUE & HOTEL | D19: Additional venue equipment hire | E19: 20000 | F19: Not Applicable | L19: =IF($F19="Not Applicable",0,IF(K19>0,K19,IF(J19>0,J19,IF(I19>0,I19,E19)))) -> 0 | M19: =SUMIFS('04 Payments'!$K$7:$K$400,'04 Payments'!$D$7:$D$400,$B19) -> 0 | N19: =MAX(0,L19-M19) -> 0 | P19: =L19-E19 -> -20000 | Q19: Not Started
B20: BG014 | C20: FOOD & BEVERAGE | D20: Reception buffet - adults (per head x pax) | E20: 1800000 | F20: Required | G20: Groom | L20: =IF($F20="Not Applicable",0,IF(K20>0,K20,IF(J20>0,J20,IF(I20>0,I20,E20)))) -> 1800000 | M20: =SUMIFS('04 Payments'!$K$7:$K$400,'04 Payments'!$D$7:$D$400,$B20) -> 0 | N20: =MAX(0,L20-M20) -> 1800000 | P20: =L20-E20 -> 0 | Q20: Not Started
B21: BG015 | C21: FOOD & BEVERAGE | D21: Children's meals | E21: 45000 | F21: Not Applicable | L21: =IF($F21="Not Applicable",0,IF(K21>0,K21,IF(J21>0,J21,IF(I21>0,I21,E21)))) -> 0 | M21: =SUMIFS('04 Payments'!$K$7:$K$400,'04 Payments'!$D$7:$D$400,$B21) -> 0 | N21: =MAX(0,L21-M21) -> 0 | P21: =L21-E21 -> -45000 | Q21: Not Started
B22: BG016 | C22: FOOD & BEVERAGE | D22: Welcome drinks | E22: 60000 | F22: Not Applicable | L22: =IF($F22="Not Applicable",0,IF(K22>0,K22,IF(J22>0,J22,IF(I22>0,I22,E22)))) -> 0 | M22: =SUMIFS('04 Payments'!$K$7:$K$400,'04 Payments'!$D$7:$D$400,$B22) -> 0 | N22: =MAX(0,L22-M22) -> 0 | P22: =L22-E22 -> -60000 | Q22: Not Started
B23: BG017 | C23: FOOD & BEVERAGE | D23: Canapes / short eats on arrival | E23: 70000 | F23: Not Applicable | L23: =IF($F23="Not Applicable",0,IF(K23>0,K23,IF(J23>0,J23,IF(I23>0,I23,E23)))) -> 0 | M23: =SUMIFS('04 Payments'!$K$7:$K$400,'04 Payments'!$D$7:$D$400,$B23) -> 0 | N23: =MAX(0,L23-M23) -> 0 | P23: =L23-E23 -> -70000 | Q23: Not Started
B24: BG018 | C24: FOOD & BEVERAGE | D24: Dessert counter | E24: 50000 | F24: Not Applicable | L24: =IF($F24="Not Applicable",0,IF(K24>0,K24,IF(J24>0,J24,IF(I24>0,I24,E24)))) -> 0 | M24: =SUMIFS('04 Payments'!$K$7:$K$400,'04 Payments'!$D$7:$D$400,$B24) -> 0 | N24: =MAX(0,L24-M24) -> 0 | P24: =L24-E24 -> -50000 | Q24: Not Started
B25: BG019 | C25: FOOD & BEVERAGE | D25: Tea / coffee station | E25: 25000 | F25: Required | G25: Groom's Family | L25: =IF($F25="Not Applicable",0,IF(K25>0,K25,IF(J25>0,J25,IF(I25>0,I25,E25)))) -> 25000 | M25: =SUMIFS('04 Payments'!$K$7:$K$400,'04 Payments'!$D$7:$D$400,$B25) -> 0 | N25: =MAX(0,L25-M25) -> 25000 | P25: =L25-E25 -> 0 | Q25: Not Started
B26: BG020 | C26: FOOD & BEVERAGE | D26: Bottled water | E26: 18000 | F26: Not Applicable | L26: =IF($F26="Not Applicable",0,IF(K26>0,K26,IF(J26>0,J26,IF(I26>0,I26,E26)))) -> 0 | M26: =SUMIFS('04 Payments'!$K$7:$K$400,'04 Payments'!$D$7:$D$400,$B26) -> 0 | N26: =MAX(0,L26-M26) -> 0 | P26: =L26-E26 -> -18000 | Q26: Not Started
B27: BG021 | C27: FOOD & BEVERAGE | D27: Soft drinks | E27: 45000 | F27: Required | G27: Groom's Family | L27: =IF($F27="Not Applicable",0,IF(K27>0,K27,IF(J27>0,J27,IF(I27>0,I27,E27)))) -> 45000 | M27: =SUMIFS('04 Payments'!$K$7:$K$400,'04 Payments'!$D$7:$D$400,$B27) -> 0 | N27: =MAX(0,L27-M27) -> 45000 | P27: =L27-E27 -> 0 | Q27: Not Started
B28: BG022 | C28: FOOD & BEVERAGE | D28: Alcohol - bar stock | E28: 100000 | F28: Required | G28: Groom's Family | L28: =IF($F28="Not Applicable",0,IF(K28>0,K28,IF(J28>0,J28,IF(I28>0,I28,E28)))) -> 100000 | M28: =SUMIFS('04 Payments'!$K$7:$K$400,'04 Payments'!$D$7:$D$400,$B28) -> 0 | N28: =MAX(0,L28-M28) -> 100000 | P28: =L28-E28 -> 0 | Q28: Not Started
B29: BG023 | C29: FOOD & BEVERAGE | D29: Bar service / bartender | E29: 30000 | F29: Not Applicable | L29: =IF($F29="Not Applicable",0,IF(K29>0,K29,IF(J29>0,J29,IF(I29>0,I29,E29)))) -> 0 | M29: =SUMIFS('04 Payments'!$K$7:$K$400,'04 Payments'!$D$7:$D$400,$B29) -> 0 | N29: =MAX(0,L29-M29) -> 0 | P29: =L29-E29 -> -30000 | Q29: Not Started
B30: BG024 | C30: FOOD & BEVERAGE | D30: Ice | E30: 2000 | F30: Optional | G30: Groom | L30: =IF($F30="Not Applicable",0,IF(K30>0,K30,IF(J30>0,J30,IF(I30>0,I30,E30)))) -> 2000 | M30: =SUMIFS('04 Payments'!$K$7:$K$400,'04 Payments'!$D$7:$D$400,$B30) -> 0 | N30: =MAX(0,L30-M30) -> 2000 | P30: =L30-E30 -> 0 | Q30: Not Started
B31: BG025 | C31: FOOD & BEVERAGE | D31: Vendor & crew meals | E31: 25000 | F31: Required | G31: Groom | L31: =IF($F31="Not Applicable",0,IF(K31>0,K31,IF(J31>0,J31,IF(I31>0,I31,E31)))) -> 25000 | M31: =SUMIFS('04 Payments'!$K$7:$K$400,'04 Payments'!$D$7:$D$400,$B31) -> 0 | N31: =MAX(0,L31-M31) -> 25000 | P31: =L31-E31 -> 0 | Q31: Not Started
B32: BG026 | C32: FOOD & BEVERAGE | D32: Kiribath & sweets for the Poruwa | E32: 10000 | F32: Required | G32: Groom | L32: =IF($F32="Not Applicable",0,IF(K32>0,K32,IF(J32>0,J32,IF(I32>0,I32,E32)))) -> 10000 | M32: =SUMIFS('04 Payments'!$K$7:$K$400,'04 Payments'!$D$7:$D$400,$B32) -> 0 | N32: =MAX(0,L32-M32) -> 10000 | P32: =L32-E32 -> 0 | Q32: Not Started
B33: BG027 | C33: FOOD & BEVERAGE | D33: Late-night snack | E33: 0 | F33: Not Applicable | L33: =IF($F33="Not Applicable",0,IF(K33>0,K33,IF(J33>0,J33,IF(I33>0,I33,E33)))) -> 0 | M33: =SUMIFS('04 Payments'!$K$7:$K$400,'04 Payments'!$D$7:$D$400,$B33) -> 0 | N33: =MAX(0,L33-M33) -> 0 | P33: =L33-E33 -> 0 | Q33: Not Started
B34: BG028 | C34: CAKE | D34: Wedding cake (tiers) | E34: 30000 | F34: Required | G34: Shared | L34: =IF($F34="Not Applicable",0,IF(K34>0,K34,IF(J34>0,J34,IF(I34>0,I34,E34)))) -> 30000 | M34: =SUMIFS('04 Payments'!$K$7:$K$400,'04 Payments'!$D$7:$D$400,$B34) -> 0 | N34: =MAX(0,L34-M34) -> 30000 | P34: =L34-E34 -> 0 | Q34: Not Started
B35: BG029 | C35: CAKE | D35: Boxed cake pieces for guests | E35: 90000 | F35: Required | G35: Shared | L35: =IF($F35="Not Applicable",0,IF(K35>0,K35,IF(J35>0,J35,IF(I35>0,I35,E35)))) -> 90000 | M35: =SUMIFS('04 Payments'!$K$7:$K$400,'04 Payments'!$D$7:$D$400,$B35) -> 0 | N35: =MAX(0,L35-M35) -> 90000 | P35: =L35-E35 -> 0 | Q35: Not Started
B36: BG030 | C36: CAKE | D36: Cake stand & knife hire | E36: 6000 | F36: Not Applicable | L36: =IF($F36="Not Applicable",0,IF(K36>0,K36,IF(J36>0,J36,IF(I36>0,I36,E36)))) -> 0 | M36: =SUMIFS('04 Payments'!$K$7:$K$400,'04 Payments'!$D$7:$D$400,$B36) -> 0 | N36: =MAX(0,L36-M36) -> 0 | P36: =L36-E36 -> -6000 | Q36: Not Started
B37: BG031 | C37: CAKE | D37: Cake topper | E37: 4000 | F37: Not Applicable | L37: =IF($F37="Not Applicable",0,IF(K37>0,K37,IF(J37>0,J37,IF(I37>0,I37,E37)))) -> 0 | M37: =SUMIFS('04 Payments'!$K$7:$K$400,'04 Payments'!$D$7:$D$400,$B37) -> 0 | N37: =MAX(0,L37-M37) -> 0 | P37: =L37-E37 -> -4000 | Q37: Not Started
B38: BG032 | C38: CAKE | D38: Cake delivery & setup | E38: 5000 | F38: Not Applicable | L38: =IF($F38="Not Applicable",0,IF(K38>0,K38,IF(J38>0,J38,IF(I38>0,I38,E38)))) -> 0 | M38: =SUMIFS('04 Payments'!$K$7:$K$400,'04 Payments'!$D$7:$D$400,$B38) -> 0 | N38: =MAX(0,L38-M38) -> 0 | P38: =L38-E38 -> -5000 | Q38: Not Started
B39: BG033 | C39: PHOTOGRAPHY | D39: Pre-shoot photography | E39: 20000 | F39: Required | G39: Groom | L39: =IF($F39="Not Applicable",0,IF(K39>0,K39,IF(J39>0,J39,IF(I39>0,I39,E39)))) -> 20000 | M39: =SUMIFS('04 Payments'!$K$7:$K$400,'04 Payments'!$D$7:$D$400,$B39) -> 0 | N39: =MAX(0,L39-M39) -> 20000 | P39: =L39-E39 -> 0 | Q39: Not Started
B40: BG034 | C40: PHOTOGRAPHY | D40: Wedding-day photography | E40: 150000 | F40: Required | G40: Groom | L40: =IF($F40="Not Applicable",0,IF(K40>0,K40,IF(J40>0,J40,IF(I40>0,I40,E40)))) -> 150000 | M40: =SUMIFS('04 Payments'!$K$7:$K$400,'04 Payments'!$D$7:$D$400,$B40) -> 0 | N40: =MAX(0,L40-M40) -> 150000 | P40: =L40-E40 -> 0 | Q40: Not Started
B41: BG035 | C41: PHOTOGRAPHY | D41: Second photographer | E41: 45000 | F41: Not Applicable | L41: =IF($F41="Not Applicable",0,IF(K41>0,K41,IF(J41>0,J41,IF(I41>0,I41,E41)))) -> 0 | M41: =SUMIFS('04 Payments'!$K$7:$K$400,'04 Payments'!$D$7:$D$400,$B41) -> 0 | N41: =MAX(0,L41-M41) -> 0 | P41: =L41-E41 -> -45000 | Q41: Not Started
B42: BG036 | C42: PHOTOGRAPHY | D42: Assistant | E42: 15000 | F42: Not Applicable | L42: =IF($F42="Not Applicable",0,IF(K42>0,K42,IF(J42>0,J42,IF(I42>0,I42,E42)))) -> 0 | M42: =SUMIFS('04 Payments'!$K$7:$K$400,'04 Payments'!$D$7:$D$400,$B42) -> 0 | N42: =MAX(0,L42-M42) -> 0 | P42: =L42-E42 -> -15000 | Q42: Not Started
...

Sheet 04 Payments
B2: PAYMENT & EXPENSE LEDGER
B3: One row per payment, planned or made. Type the Budget ID (column B on 03 Budget) and the category and line item fill themselves. This is the only place money is recorded - 03 Budget and 05 Vendors both read from it.
F5: TOTALS | I5: =SUM(I7:I400) -> 896000 | K5: =SUM(K7:K400) -> 896000 | M5: =SUM(M7:M400) -> 0
B6: ID | C6: Date raised | D6: Budget ID (type it in) | E6: Category (auto) | F6: Line item (auto) | G6: VENDOR (pick from the list) | H6: Payment stage | I6: Amount due | J6: Due date | K6: Amount paid | L6: Paid on | M6: Balance | N6: Method | O6: Reference | P6: Refundable? | Q6: Receipt? | R6: Receipt kept where | S6: STATUS | T6: Paid by | U6: Notes
B7: =IF($D7="","","PY"&TEXT(ROW()-6,"000")) -> PY001 | D7: BG077 | E7: {=IFERROR(INDEX('03 Budget'!$C$7:$C$300,MATCH($D7,'03 Budget'!$B$7:$B$300,0)),IF($D7="","","** ID not found **"))} -> JEWELLERY | F7: {=IFERROR(INDEX('03 Budget'!$D$7:$D$300,MATCH($D7,'03 Budget'!$B$7:$B$300,0)),IF($D7="","","** ID not found **"))} -> Bridal necklace set | G7: panadura gold house | H7: Final Payment | I7: 395000 | K7: 395000 | L7: 46268 | M7: =IF(I7="","",MAX(0,I7-K7)) -> 0 | N7: Card | Q7: Yes | R7: With me | S7: =IF(I7="","",IF(K7>=I7,"Paid",IF(J7="","Not Due",IF(J7<TODAY(),"Overdue",IF(J7<=TODAY()+7,"Due",IF(J7<=TODAY()+30,"Due Soon","Not Due")))))) -> Paid
B8: =IF($D8="","","PY"&TEXT(ROW()-6,"000")) -> PY002 | D8: BG082 | E8: {=IFERROR(INDEX('03 Budget'!$C$7:$C$300,MATCH($D8,'03 Budget'!$B$7:$B$300,0)),IF($D8="","","** ID not found **"))} -> JEWELLERY | F8: {=IFERROR(INDEX('03 Budget'!$D$7:$D$300,MATCH($D8,'03 Budget'!$B$7:$B$300,0)),IF($D8="","","** ID not found **"))} -> Wedding rings (pair) | G8: panadura gold house | H8: Final Payment | I8: 485000 | K8: 485000 | L8: 46268 | M8: =IF(I8="","",MAX(0,I8-K8)) -> 0 | N8: Card | Q8: Yes | R8: With me | S8: =IF(I8="","",IF(K8>=I8,"Paid",IF(J8="","Not Due",IF(J8<TODAY(),"Overdue",IF(J8<=TODAY()+7,"Due",IF(J8<=TODAY()+30,"Due Soon","Not Due")))))) -> Paid
B9: =IF($D9="","","PY"&TEXT(ROW()-6,"000")) -> PY003 | D9: BG083 | E9: {=IFERROR(INDEX('03 Budget'!$C$7:$C$300,MATCH($D9,'03 Budget'!$B$7:$B$300,0)),IF($D9="","","** ID not found **"))} -> JEWELLERY | F9: {=IFERROR(INDEX('03 Budget'!$D$7:$D$300,MATCH($D9,'03 Budget'!$B$7:$B$300,0)),IF($D9="","","** ID not found **"))} -> Bride's brother ring | G9: panadura gold house | H9: Final Payment | I9: 16000 | K9: 16000 | L9: 46268 | M9: =IF(I9="","",MAX(0,I9-K9)) -> 0 | N9: Card | Q9: Yes | R9: With me | S9: =IF(I9="","",IF(K9>=I9,"Paid",IF(J9="","Not Due",IF(J9<TODAY(),"Overdue",IF(J9<=TODAY()+7,"Due",IF(J9<=TODAY()+30,"Due Soon","Not Due")))))) -> Paid
B10: =IF($D10="","","PY"&TEXT(ROW()-6,"000")) | E10: {=IFERROR(INDEX('03 Budget'!$C$7:$C$300,MATCH($D10,'03 Budget'!$B$7:$B$300,0)),IF($D10="","","** ID not found **"))} | F10: {=IFERROR(INDEX('03 Budget'!$D$7:$D$300,MATCH($D10,'03 Budget'!$B$7:$B$300,0)),IF($D10="","","** ID not found **"))} | M10: =IF(I10="","",MAX(0,I10-K10)) | S10: =IF(I10="","",IF(K10>=I10,"Paid",IF(J10="","Not Due",IF(J10<TODAY(),"Overdue",IF(J10<=TODAY()+7,"Due",IF(J10<=TODAY()+30,"Due Soon","Not Due"))))))
B11: =IF($D11="","","PY"&TEXT(ROW()-6,"000")) | E11: {=IFERROR(INDEX('03 Budget'!$C$7:$C$300,MATCH($D11,'03 Budget'!$B$7:$B$300,0)),IF($D11="","","** ID not found **"))} | F11: {=IFERROR(INDEX('03 Budget'!$D$7:$D$300,MATCH($D11,'03 Budget'!$B$7:$B$300,0)),IF($D11="","","** ID not found **"))} | M11: =IF(I11="","",MAX(0,I11-K11)) | S11: =IF(I11="","",IF(K11>=I11,"Paid",IF(J11="","Not Due",IF(J11<TODAY(),"Overdue",IF(J11<=TODAY()+7,"Due",IF(J11<=TODAY()+30,"Due Soon","Not Due"))))))
B12: =IF($D12="","","PY"&TEXT(ROW()-6,"000")) | E12: {=IFERROR(INDEX('03 Budget'!$C$7:$C$300,MATCH($D12,'03 Budget'!$B$7:$B$300,0)),IF($D12="","","** ID not found **"))} | F12: {=IFERROR(INDEX('03 Budget'!$D$7:$D$300,MATCH($D12,'03 Budget'!$B$7:$B$300,0)),IF($D12="","","** ID not found **"))} | M12: =IF(I12="","",MAX(0,I12-K12)) | S12: =IF(I12="","",IF(K12>=I12,"Paid",IF(J12="","Not Due",IF(J12<TODAY(),"Overdue",IF(J12<=TODAY()+7,"Due",IF(J12<=TODAY()+30,"Due Soon","Not Due"))))))
B13: =IF($D13="","","PY"&TEXT(ROW()-6,"000")) | E13: {=IFERROR(INDEX('03 Budget'!$C$7:$C$300,MATCH($D13,'03 Budget'!$B$7:$B$300,0)),IF($D13="","","** ID not found **"))} | F13: {=IFERROR(INDEX('03 Budget'!$D$7:$D$300,MATCH($D13,'03 Budget'!$B$7:$B$300,0)),IF($D13="","","** ID not found **"))} | M13: =IF(I13="","",MAX(0,I13-K13)) | S13: =IF(I13="","",IF(K13>=I13,"Paid",IF(J13="","Not Due",IF(J13<TODAY(),"Overdue",IF(J13<=TODAY()+7,"Due",IF(J13<=TODAY()+30,"Due Soon","Not Due"))))))
B14: =IF($D14="","","PY"&TEXT(ROW()-6,"000")) | E14: {=IFERROR(INDEX('03 Budget'!$C$7:$C$300,MATCH($D14,'03 Budget'!$B$7:$B$300,0)),IF($D14="","","** ID not found **"))} | F14: {=IFERROR(INDEX('03 Budget'!$D$7:$D$300,MATCH($D14,'03 Budget'!$B$7:$B$300,0)),IF($D14="","","** ID not found **"))} | M14: =IF(I14="","",MAX(0,I14-K14)) | S14: =IF(I14="","",IF(K14>=I14,"Paid",IF(J14="","Not Due",IF(J14<TODAY(),"Overdue",IF(J14<=TODAY()+7,"Due",IF(J14<=TODAY()+30,"Due Soon","Not Due"))))))
B15: =IF($D15="","","PY"&TEXT(ROW()-6,"000")) | E15: {=IFERROR(INDEX('03 Budget'!$C$7:$C$300,MATCH($D15,'03 Budget'!$B$7:$B$300,0)),IF($D15="","","** ID not found **"))} | F15: {=IFERROR(INDEX('03 Budget'!$D$7:$D$300,MATCH($D15,'03 Budget'!$B$7:$B$300,0)),IF($D15="","","** ID not found **"))} | M15: =IF(I15="","",MAX(0,I15-K15)) | S15: =IF(I15="","",IF(K15>=I15,"Paid",IF(J15="","Not Due",IF(J15<TODAY(),"Overdue",IF(J15<=TODAY()+7,"Due",IF(J15<=TODAY()+30,"Due Soon","Not Due"))))))
B16: =IF($D16="","","PY"&TEXT(ROW()-6,"000")) | E16: {=IFERROR(INDEX('03 Budget'!$C$7:$C$300,MATCH($D16,'03 Budget'!$B$7:$B$300,0)),IF($D16="","","** ID not found **"))} | F16: {=IFERROR(INDEX('03 Budget'!$D$7:$D$300,MATCH($D16,'03 Budget'!$B$7:$B$300,0)),IF($D16="","","** ID not found **"))} | M16: =IF(I16="","",MAX(0,I16-K16)) | S16: =IF(I16="","",IF(K16>=I16,"Paid",IF(J16="","Not Due",IF(J16<TODAY(),"Overdue",IF(J16<=TODAY()+7,"Due",IF(J16<=TODAY()+30,"Due Soon","Not Due"))))))
B17: =IF($D17="","","PY"&TEXT(ROW()-6,"000")) | E17: {=IFERROR(INDEX('03 Budget'!$C$7:$C$300,MATCH($D17,'03 Budget'!$B$7:$B$300,0)),IF($D17="","","** ID not found **"))} | F17: {=IFERROR(INDEX('03 Budget'!$D$7:$D$300,MATCH($D17,'03 Budget'!$B$7:$B$300,0)),IF($D17="","","** ID not found **"))} | M17: =IF(I17="","",MAX(0,I17-K17)) | S17: =IF(I17="","",IF(K17>=I17,"Paid",IF(J17="","Not Due",IF(J17<TODAY(),"Overdue",IF(J17<=TODAY()+7,"Due",IF(J17<=TODAY()+30,"Due Soon","Not Due"))))))
B18: =IF($D18="","","PY"&TEXT(ROW()-6,"000")) | E18: {=IFERROR(INDEX('03 Budget'!$C$7:$C$300,MATCH($D18,'03 Budget'!$B$7:$B$300,0)),IF($D18="","","** ID not found **"))} | F18: {=IFERROR(INDEX('03 Budget'!$D$7:$D$300,MATCH($D18,'03 Budget'!$B$7:$B$300,0)),IF($D18="","","** ID not found **"))} | M18: =IF(I18="","",MAX(0,I18-K18)) | S18: =IF(I18="","",IF(K18>=I18,"Paid",IF(J18="","Not Due",IF(J18<TODAY(),"Overdue",IF(J18<=TODAY()+7,"Due",IF(J18<=TODAY()+30,"Due Soon","Not Due"))))))
B19: =IF($D19="","","PY"&TEXT(ROW()-6,"000")) | E19: {=IFERROR(INDEX('03 Budget'!$C$7:$C$300,MATCH($D19,'03 Budget'!$B$7:$B$300,0)),IF($D19="","","** ID not found **"))} | F19: {=IFERROR(INDEX('03 Budget'!$D$7:$D$300,MATCH($D19,'03 Budget'!$B$7:$B$300,0)),IF($D19="","","** ID not found **"))} | M19: =IF(I19="","",MAX(0,I19-K19)) | S19: =IF(I19="","",IF(K19>=I19,"Paid",IF(J19="","Not Due",IF(J19<TODAY(),"Overdue",IF(J19<=TODAY()+7,"Due",IF(J19<=TODAY()+30,"Due Soon","Not Due"))))))
B20: =IF($D20="","","PY"&TEXT(ROW()-6,"000")) | E20: {=IFERROR(INDEX('03 Budget'!$C$7:$C$300,MATCH($D20,'03 Budget'!$B$7:$B$300,0)),IF($D20="","","** ID not found **"))} | F20: {=IFERROR(INDEX('03 Budget'!$D$7:$D$300,MATCH($D20,'03 Budget'!$B$7:$B$300,0)),IF($D20="","","** ID not found **"))} | M20: =IF(I20="","",MAX(0,I20-K20)) | S20: =IF(I20="","",IF(K20>=I20,"Paid",IF(J20="","Not Due",IF(J20<TODAY(),"Overdue",IF(J20<=TODAY()+7,"Due",IF(J20<=TODAY()+30,"Due Soon","Not Due"))))))
B21: =IF($D21="","","PY"&TEXT(ROW()-6,"000")) | E21: {=IFERROR(INDEX('03 Budget'!$C$7:$C$300,MATCH($D21,'03 Budget'!$B$7:$B$300,0)),IF($D21="","","** ID not found **"))} | F21: {=IFERROR(INDEX('03 Budget'!$D$7:$D$300,MATCH($D21,'03 Budget'!$B$7:$B$300,0)),IF($D21="","","** ID not found **"))} | M21: =IF(I21="","",MAX(0,I21-K21)) | S21: =IF(I21="","",IF(K21>=I21,"Paid",IF(J21="","Not Due",IF(J21<TODAY(),"Overdue",IF(J21<=TODAY()+7,"Due",IF(J21<=TODAY()+30,"Due Soon","Not Due"))))))
... B400: =IF($D400="","","PY"&TEXT(ROW()-6,"000")) | E400: {=IFERROR(INDEX('03 Budget'!$C$7:$C$300,MATCH($D400,'03 Budget'!$B$7:$B$300,0)),IF($D400="","","** ID not found **"))} | F400: {=IFERROR(INDEX('03 Budget'!$D$7:$D$300,MATCH($D400,'03 Budget'!$B$7:$B$300,0)),IF($D400="","","** ID not found **"))} | M400: =IF(I400="","",MAX(0,I400-K400)) | S400: =IF(I400="","",IF(K400>=I400,"Paid",IF(J400="","Not Due",IF(J400<TODAY(),"Overdue",IF(J400<=TODAY()+7,"Due",IF(J400<=TODAY()+30,"Due Soon","Not Due"))))))

Sheet 05 Vendors
B2: VENDOR MASTER
B3: Enter every supplier ONCE here. Compare your shortlist and work through the questions on 05a Vendor Compare first, then record the winner here - the rest of the workbook reads from this sheet.
B6: ID | C6: Category | D6: Vendor name | E6: Contact person | F6: Phone | G6: WhatsApp | H6: Email | I6: Address | J6: Package / inclusions | K6: Quoted | L6: Negotiated | M6: Deposit paid | N6: Total paid | O6: Balance owing | P6: Overdue payments | Q6: Contract signed? | R6: Contract kept where | S6: Booking status | T6: Arrival time | U6: Setup done by | V6: Finish time | W6: Overtime rate | X6: Key deliverables | Y6: Final confirmation date | Z6: Rating /5 | AA6: Notes
B7: V001 | C7: Venue / Hotel | D7: [Hotel name] | M7: =SUMIFS('04 Payments'!$K$7:$K$400,'04 Payments'!$G$7:$G$400,$D7,'04 Payments'!$H$7:$H$400,"Booking Deposit") -> 0 | N7: =SUMIFS('04 Payments'!$K$7:$K$400,'04 Payments'!$G$7:$G$400,$D7) -> 0 | O7: =IF(L7>0,L7-N7,IF(K7>0,K7-N7,0)) -> 0 | P7: =COUNTIFS('04 Payments'!$G$7:$G$400,$D7,'04 Payments'!$S$7:$S$400,"Overdue") -> 0 | S7: Confirmed
B8: V002 | C8: Caterer | D8: [In-house catering] | M8: =SUMIFS('04 Payments'!$K$7:$K$400,'04 Payments'!$G$7:$G$400,$D8,'04 Payments'!$H$7:$H$400,"Booking Deposit") -> 0 | N8: =SUMIFS('04 Payments'!$K$7:$K$400,'04 Payments'!$G$7:$G$400,$D8) -> 0 | O8: =IF(L8>0,L8-N8,IF(K8>0,K8-N8,0)) -> 0 | P8: =COUNTIFS('04 Payments'!$G$7:$G$400,$D8,'04 Payments'!$S$7:$S$400,"Overdue") -> 0 | S8: Confirmed
B9: V003 | C9: Photographer | D9: [Studio name] | M9: =SUMIFS('04 Payments'!$K$7:$K$400,'04 Payments'!$G$7:$G$400,$D9,'04 Payments'!$H$7:$H$400,"Booking Deposit") -> 0 | N9: =SUMIFS('04 Payments'!$K$7:$K$400,'04 Payments'!$G$7:$G$400,$D9) -> 0 | O9: =IF(L9>0,L9-N9,IF(K9>0,K9-N9,0)) -> 0 | P9: =COUNTIFS('04 Payments'!$G$7:$G$400,$D9,'04 Payments'!$S$7:$S$400,"Overdue") -> 0 | S9: Shortlisted
B10: V004 | C10: Videographer | D10: [Studio name] | M10: =SUMIFS('04 Payments'!$K$7:$K$400,'04 Payments'!$G$7:$G$400,$D10,'04 Payments'!$H$7:$H$400,"Booking Deposit") -> 0 | N10: =SUMIFS('04 Payments'!$K$7:$K$400,'04 Payments'!$G$7:$G$400,$D10) -> 0 | O10: =IF(L10>0,L10-N10,IF(K10>0,K10-N10,0)) -> 0 | P10: =COUNTIFS('04 Payments'!$G$7:$G$400,$D10,'04 Payments'!$S$7:$S$400,"Overdue") -> 0 | S10: Shortlisted
B11: V005 | C11: Makeup Artist | D11: [Bridal dresser] | M11: =SUMIFS('04 Payments'!$K$7:$K$400,'04 Payments'!$G$7:$G$400,$D11,'04 Payments'!$H$7:$H$400,"Booking Deposit") -> 0 | N11: =SUMIFS('04 Payments'!$K$7:$K$400,'04 Payments'!$G$7:$G$400,$D11) -> 0 | O11: =IF(L11>0,L11-N11,IF(K11>0,K11-N11,0)) -> 0 | P11: =COUNTIFS('04 Payments'!$G$7:$G$400,$D11,'04 Payments'!$S$7:$S$400,"Overdue") -> 0 | S11: Shortlisted
B12: V006 | C12: Saree / Dress Designer | D12: [Designer] | M12: =SUMIFS('04 Payments'!$K$7:$K$400,'04 Payments'!$G$7:$G$400,$D12,'04 Payments'!$H$7:$H$400,"Booking Deposit") -> 0 | N12: =SUMIFS('04 Payments'!$K$7:$K$400,'04 Payments'!$G$7:$G$400,$D12) -> 0 | O12: =IF(L12>0,L12-N12,IF(K12>0,K12-N12,0)) -> 0 | P12: =COUNTIFS('04 Payments'!$G$7:$G$400,$D12,'04 Payments'!$S$7:$S$400,"Overdue") -> 0 | S12: Researching
B13: V007 | C13: Jewellery | D13: Panadura Gold House | E13: Ismi | F13: 705116588 | G13: 765816588 | H13: pghjewel@gmail.com | I13: panadura | K13: 900000 | L13: 896000 | M13: =SUMIFS('04 Payments'!$K$7:$K$400,'04 Payments'!$G$7:$G$400,$D13,'04 Payments'!$H$7:$H$400,"Booking Deposit") -> 0 | N13: 896000 | O13: =IF(L13>0,L13-N13,IF(K13>0,K13-N13,0)) -> 0 | P13: =COUNTIFS('04 Payments'!$G$7:$G$400,$D13,'04 Payments'!$S$7:$S$400,"Overdue") -> 0 | Q13: Yes | R13: with me | S13: Completed | T13: 46295 | Y13: 46295 | Z13: 5
B14: V008 | C14: Decorator | D14: [Decorator] | M14: =SUMIFS('04 Payments'!$K$7:$K$400,'04 Payments'!$G$7:$G$400,$D14,'04 Payments'!$H$7:$H$400,"Booking Deposit") -> 0 | N14: =SUMIFS('04 Payments'!$K$7:$K$400,'04 Payments'!$G$7:$G$400,$D14) -> 0 | O14: =IF(L14>0,L14-N14,IF(K14>0,K14-N14,0)) -> 0 | P14: =COUNTIFS('04 Payments'!$G$7:$G$400,$D14,'04 Payments'!$S$7:$S$400,"Overdue") -> 0 | S14: Researching
B15: V009 | C15: Cake | D15: [Bakery] | M15: =SUMIFS('04 Payments'!$K$7:$K$400,'04 Payments'!$G$7:$G$400,$D15,'04 Payments'!$H$7:$H$400,"Booking Deposit") -> 0 | N15: =SUMIFS('04 Payments'!$K$7:$K$400,'04 Payments'!$G$7:$G$400,$D15) -> 0 | O15: =IF(L15>0,L15-N15,IF(K15>0,K15-N15,0)) -> 0 | P15: =COUNTIFS('04 Payments'!$G$7:$G$400,$D15,'04 Payments'!$S$7:$S$400,"Overdue") -> 0 | S15: Researching
B16: V010 | C16: Kandyan Dancers | D16: [Dance troupe] | M16: =SUMIFS('04 Payments'!$K$7:$K$400,'04 Payments'!$G$7:$G$400,$D16,'04 Payments'!$H$7:$H$400,"Booking Deposit") -> 0 | N16: =SUMIFS('04 Payments'!$K$7:$K$400,'04 Payments'!$G$7:$G$400,$D16) -> 0 | O16: =IF(L16>0,L16-N16,IF(K16>0,K16-N16,0)) -> 0 | P16: =COUNTIFS('04 Payments'!$G$7:$G$400,$D16,'04 Payments'!$S$7:$S$400,"Overdue") -> 0 | S16: Researching
B17: V011 | C17: Drummers | D17: [Hewisi group] | M17: =SUMIFS('04 Payments'!$K$7:$K$400,'04 Payments'!$G$7:$G$400,$D17,'04 Payments'!$H$7:$H$400,"Booking Deposit") -> 0 | N17: =SUMIFS('04 Payments'!$K$7:$K$400,'04 Payments'!$G$7:$G$400,$D17) -> 0 | O17: =IF(L17>0,L17-N17,IF(K17>0,K17-N17,0)) -> 0 | P17: =COUNTIFS('04 Payments'!$G$7:$G$400,$D17,'04 Payments'!$S$7:$S$400,"Overdue") -> 0 | S17: Researching
B18: V012 | C18: Poruwa Officiant | D18: [Ashtaka chanter] | M18: =SUMIFS('04 Payments'!$K$7:$K$400,'04 Payments'!$G$7:$G$400,$D18,'04 Payments'!$H$7:$H$400,"Booking Deposit") -> 0 | N18: =SUMIFS('04 Payments'!$K$7:$K$400,'04 Payments'!$G$7:$G$400,$D18) -> 0 | O18: =IF(L18>0,L18-N18,IF(K18>0,K18-N18,0)) -> 0 | P18: =COUNTIFS('04 Payments'!$G$7:$G$400,$D18,'04 Payments'!$S$7:$S$400,"Overdue") -> 0 | S18: Researching
B19: V013 | C19: MC | D19: [MC name] | M19: =SUMIFS('04 Payments'!$K$7:$K$400,'04 Payments'!$G$7:$G$400,$D19,'04 Payments'!$H$7:$H$400,"Booking Deposit") -> 0 | N19: =SUMIFS('04 Payments'!$K$7:$K$400,'04 Payments'!$G$7:$G$400,$D19) -> 0 | O19: =IF(L19>0,L19-N19,IF(K19>0,K19-N19,0)) -> 0 | P19: =COUNTIFS('04 Payments'!$G$7:$G$400,$D19,'04 Payments'!$S$7:$S$400,"Overdue") -> 0 | S19: Researching
B20: V014 | C20: DJ | D20: [DJ name] | M20: =SUMIFS('04 Payments'!$K$7:$K$400,'04 Payments'!$G$7:$G$400,$D20,'04 Payments'!$H$7:$H$400,"Booking Deposit") -> 0 | N20: =SUMIFS('04 Payments'!$K$7:$K$400,'04 Payments'!$G$7:$G$400,$D20) -> 0 | O20: =IF(L20>0,L20-N20,IF(K20>0,K20-N20,0)) -> 0 | P20: =COUNTIFS('04 Payments'!$G$7:$G$400,$D20,'04 Payments'!$S$7:$S$400,"Overdue") -> 0 | S20: Researching
B21: V015 | C21: Transport | D21: [Bridal car hire] | M21: =SUMIFS('04 Payments'!$K$7:$K$400,'04 Payments'!$G$7:$G$400,$D21,'04 Payments'!$H$7:$H$400,"Booking Deposit") -> 0 | N21: =SUMIFS('04 Payments'!$K$7:$K$400,'04 Payments'!$G$7:$G$400,$D21) -> 0 | O21: =IF(L21>0,L21-N21,IF(K21>0,K21-N21,0)) -> 0 | P21: =COUNTIFS('04 Payments'!$G$7:$G$400,$D21,'04 Payments'!$S$7:$S$400,"Overdue") -> 0 | S21: Researching
B22: V016 | C22: Printing / Invitations | D22: [Printer] | M22: =SUMIFS('04 Payments'!$K$7:$K$400,'04 Payments'!$G$7:$G$400,$D22,'04 Payments'!$H$7:$H$400,"Booking Deposit") -> 0 | N22: =SUMIFS('04 Payments'!$K$7:$K$400,'04 Payments'!$G$7:$G$400,$D22) -> 0 | O22: =IF(L22>0,L22-N22,IF(K22>0,K22-N22,0)) -> 0 | P22: =COUNTIFS('04 Payments'!$G$7:$G$400,$D22,'04 Payments'!$S$7:$S$400,"Overdue") -> 0 | S22: Researching
B23: V017 | C23: Sound & AV | D23: [AV supplier] | M23: =SUMIFS('04 Payments'!$K$7:$K$400,'04 Payments'!$G$7:$G$400,$D23,'04 Payments'!$H$7:$H$400,"Booking Deposit") -> 0 | N23: =SUMIFS('04 Payments'!$K$7:$K$400,'04 Payments'!$G$7:$G$400,$D23) -> 0 | O23: =IF(L23>0,L23-N23,IF(K23>0,K23-N23,0)) -> 0 | P23: =COUNTIFS('04 Payments'!$G$7:$G$400,$D23,'04 Payments'!$S$7:$S$400,"Overdue") -> 0 | S23: Researching
B24: V018 | C24: Coordinator | D24: [Coordinator] | M24: =SUMIFS('04 Payments'!$K$7:$K$400,'04 Payments'!$G$7:$G$400,$D24,'04 Payments'!$H$7:$H$400,"Booking Deposit") -> 0 | N24: =SUMIFS('04 Payments'!$K$7:$K$400,'04 Payments'!$G$7:$G$400,$D24) -> 0 | O24: =IF(L24>0,L24-N24,IF(K24>0,K24-N24,0)) -> 0 | P24: =COUNTIFS('04 Payments'!$G$7:$G$400,$D24,'04 Payments'!$S$7:$S$400,"Overdue") -> 0 | S24: Researching
M25: =SUMIFS('04 Payments'!$K$7:$K$400,'04 Payments'!$G$7:$G$400,$D25,'04 Payments'!$H$7:$H$400,"Booking Deposit") -> 0 | N25: =SUMIFS('04 Payments'!$K$7:$K$400,'04 Payments'!$G$7:$G$400,$D25) -> 0 | O25: =IF(L25>0,L25-N25,IF(K25>0,K25-N25,0)) -> 0 | P25: =COUNTIFS('04 Payments'!$G$7:$G$400,$D25,'04 Payments'!$S$7:$S$400,"Overdue") -> 0
M26: =SUMIFS('04 Payments'!$K$7:$K$400,'04 Payments'!$G$7:$G$400,$D26,'04 Payments'!$H$7:$H$400,"Booking Deposit") -> 0 | N26: =SUMIFS('04 Payments'!$K$7:$K$400,'04 Payments'!$G$7:$G$400,$D26) -> 0 | O26: =IF(L26>0,L26-N26,IF(K26>0,K26-N26,0)) -> 0 | P26: =COUNTIFS('04 Payments'!$G$7:$G$400,$D26,'04 Payments'!$S$7:$S$400,"Overdue") -> 0
M27: =SUMIFS('04 Payments'!$K$7:$K$400,'04 Payments'!$G$7:$G$400,$D27,'04 Payments'!$H$7:$H$400,"Booking Deposit") -> 0 | N27: =SUMIFS('04 Payments'!$K$7:$K$400,'04 Payments'!$G$7:$G$400,$D27) -> 0 | O27: =IF(L27>0,L27-N27,IF(K27>0,K27-N27,0)) -> 0 | P27: =COUNTIFS('04 Payments'!$G$7:$G$400,$D27,'04 Payments'!$S$7:$S$400,"Overdue") -> 0
M28: =SUMIFS('04 Payments'!$K$7:$K$400,'04 Payments'!$G$7:$G$400,$D28,'04 Payments'!$H$7:$H$400,"Booking Deposit") -> 0 | N28: =SUMIFS('04 Payments'!$K$7:$K$400,'04 Payments'!$G$7:$G$400,$D28) -> 0 | O28: =IF(L28>0,L28-N28,IF(K28>0,K28-N28,0)) -> 0 | P28: =COUNTIFS('04 Payments'!$G$7:$G$400,$D28,'04 Payments'!$S$7:$S$400,"Overdue") -> 0
M29: =SUMIFS('04 Payments'!$K$7:$K$400,'04 Payments'!$G$7:$G$400,$D29,'04 Payments'!$H$7:$H$400,"Booking Deposit") -> 0 | N29: =SUMIFS('04 Payments'!$K$7:$K$400,'04 Payments'!$G$7:$G$400,$D29) -> 0 | O29: =IF(L29>0,L29-N29,IF(K29>0,K29-N29,0)) -> 0 | P29: =COUNTIFS('04 Payments'!$G$7:$G$400,$D29,'04 Payments'!$S$7:$S$400,"Overdue") -> 0
M30: =SUMIFS('04 Payments'!$K$7:$K$400,'04 Payments'!$G$7:$G$400,$D30,'04 Payments'!$H$7:$H$400,"Booking Deposit") -> 0 | N30: =SUMIFS('04 Payments'!$K$7:$K$400,'04 Payments'!$G$7:$G$400,$D30) -> 0 | O30: =IF(L30>0,L30-N30,IF(K30>0,K30-N30,0)) -> 0 | P30: =COUNTIFS('04 Payments'!$G$7:$G$400,$D30,'04 Payments'!$S$7:$S$400,"Overdue") -> 0
M31: =SUMIFS('04 Payments'!$K$7:$K$400,'04 Payments'!$G$7:$G$400,$D31,'04 Payments'!$H$7:$H$400,"Booking Deposit") -> 0 | N31: =SUMIFS('04 Payments'!$K$7:$K$400,'04 Payments'!$G$7:$G$400,$D31) -> 0 | O31: =IF(L31>0,L31-N31,IF(K31>0,K31-N31,0)) -> 0 | P31: =COUNTIFS('04 Payments'!$G$7:$G$400,$D31,'04 Payments'!$S$7:$S$400,"Overdue") -> 0
M32: =SUMIFS('04 Payments'!$K$7:$K$400,'04 Payments'!$G$7:$G$400,$D32,'04 Payments'!$H$7:$H$400,"Booking Deposit") -> 0 | N32: =SUMIFS('04 Payments'!$K$7:$K$400,'04 Payments'!$G$7:$G$400,$D32) -> 0 | O32: =IF(L32>0,L32-N32,IF(K32>0,K32-N32,0)) -> 0 | P32: =COUNTIFS('04 Payments'!$G$7:$G$400,$D32,'04 Payments'!$S$7:$S$400,"Overdue") -> 0
M33: =SUMIFS('04 Payments'!$K$7:$K$400,'04 Payments'!$G$7:$G$400,$D33,'04 Payments'!$H$7:$H$400,"Booking Deposit") -> 0 | N33: =SUMIFS('04 Payments'!$K$7:$K$400,'04 Payments'!$G$7:$G$400,$D33) -> 0 | O33: =IF(L33>0,L33-N33,IF(K33>0,K33-N33,0)) -> 0 | P33: =COUNTIFS('04 Payments'!$G$7:$G$400,$D33,'04 Payments'!$S$7:$S$400,"Overdue") -> 0
M34: =SUMIFS('04 Payments'!$K$7:$K$400,'04 Payments'!$G$7:$G$400,$D34,'04 Payments'!$H$7:$H$400,"Booking Deposit") -> 0 | N34: =SUMIFS('04 Payments'!$K$7:$K$400,'04 Payments'!$G$7:$G$400,$D34) -> 0 | O34: =IF(L34>0,L34-N34,IF(K34>0,K34-N34,0)) -> 0 | P34: =COUNTIFS('04 Payments'!$G$7:$G$400,$D34,'04 Payments'!$S$7:$S$400,"Overdue") -> 0
M35: =SUMIFS('04 Payments'!$K$7:$K$400,'04 Payments'!$G$7:$G$400,$D35,'04 Payments'!$H$7:$H$400,"Booking Deposit") -> 0 | N35: =SUMIFS('04 Payments'!$K$7:$K$400,'04 Payments'!$G$7:$G$400,$D35) -> 0 | O35: =IF(L35>0,L35-N35,IF(K35>0,K35-N35,0)) -> 0 | P35: =COUNTIFS('04 Payments'!$G$7:$G$400,$D35,'04 Payments'!$S$7:$S$400,"Overdue") -> 0
M36: =SUMIFS('04 Payments'!$K$7:$K$400,'04 Payments'!$G$7:$G$400,$D36,'04 Payments'!$H$7:$H$400,"Booking Deposit") -> 0 | N36: =SUMIFS('04 Payments'!$K$7:$K$400,'04 Payments'!$G$7:$G$400,$D36) -> 0 | O36: =IF(L36>0,L36-N36,IF(K36>0,K36-N36,0)) -> 0 | P36: =COUNTIFS('04 Payments'!$G$7:$G$400,$D36,'04 Payments'!$S$7:$S$400,"Overdue") -> 0
... M200: =SUMIFS('04 Payments'!$K$7:$K$400,'04 Payments'!$G$7:$G$400,$D200,'04 Payments'!$H$7:$H$400,"Booking Deposit") -> 0 | N200: =SUMIFS('04 Payments'!$K$7:$K$400,'04 Payments'!$G$7:$G$400,$D200) -> 0 | O200: =IF(L200>0,L200-N200,IF(K200>0,K200-N200,0)) -> 0 | P200: =COUNTIFS('04 Payments'!$G$7:$G$400,$D200,'04 Payments'!$S$7:$S$400,"Overdue") -> 0

Sheet 05a Vendor Compare
B2: VENDOR COMPARISON & QUESTIONS TO ASK
B3: Shortlist up to three options per vendor type, compare them side by side, and work through the questions before you commit. The DECISION row at the end of each section is what you then record in 05 Vendors.
B5: JUMP TO A SECTION - and see every decision at a glance
B6: # | C6: Row | D6: Vendor type | E6: Options entered | F6: DECISION | G6: Chosen vendor | H6: Agreed price | I6: In 05 Vendors?
B7: 1 | C7: 25 | D7: VENUE / HOTEL | E7: =COUNTA(F27:H27) -> 0 | F7: =$F$65 -> Not decided | G7: =$G$65 | H7: =$H$65 -> 0 | I7: =$I$65 -> -
B8: 2 | C8: 68 | D8: CATERER (only if separate from the hotel) | E8: =COUNTA(F70:H70) -> 0 | F8: =$F$97 -> Not decided | G8: =$G$97 | H8: =$H$97 -> 0 | I8: =$I$97 -> -
B9: 3 | C9: 100 | D9: PHOTOGRAPHER | E9: =COUNTA(F102:H102) -> 0 | F9: =$F$133 -> Not decided | G9: =$G$133 | H9: =$H$133 -> 0 | I9: =$I$133 -> -
B10: 4 | C10: 136 | D10: VIDEOGRAPHER | E10: =COUNTA(F138:H138) -> 0 | F10: =$F$165 -> Not decided | G10: =$G$165 | H10: =$H$165 -> 0 | I10: =$I$165 -> -
B11: 5 | C11: 168 | D11: DECORATOR / FLORIST | E11: =COUNTA(F170:H170) -> 0 | F11: =$F$199 -> Not decided | G11: =$G$199 | H11: =$H$199 -> 0 | I11: =$I$199 -> -
B12: 6 | C12: 202 | D12: BRIDAL DRESSER (hair & makeup) | E12: =COUNTA(F204:H204) -> 0 | F12: =$F$230 -> Not decided | G12: =$G$230 | H12: =$H$230 -> 0 | I12: =$I$230 -> -
B13: 7 | C13: 233 | D13: SAREE / DRESS DESIGNER | E13: =COUNTA(F235:H235) -> 0 | F13: =$F$260 -> Not decided | G13: =$G$260 | H13: =$H$260 -> 0 | I13: =$I$260 -> -
B14: 8 | C14: 263 | D14: JEWELLERY | E14: =COUNTA(F265:H265) -> 1 | F14: =$F$288 -> Option A | G14: =$G$288 -> Panadura Gold house | H14: =$H$288 | I14: =$I$288 -> Yes
B15: 9 | C15: 291 | D15: CAKE | E15: =COUNTA(F293:H293) -> 0 | F15: =$F$316 -> Not decided | G15: =$G$316 | H15: =$H$316 -> 0 | I15: =$I$316 -> -
B16: 10 | C16: 319 | D16: KANDYAN DANCERS & DRUMMERS | E16: =COUNTA(F321:H321) -> 0 | F16: =$F$343 -> Not decided | G16: =$G$343 | H16: =$H$343 -> 0 | I16: =$I$343 -> -
B17: 11 | C17: 346 | D17: PORUWA OFFICIANT (Ashtaka chanter) | E17: =COUNTA(F348:H348) -> 0 | F17: =$F$369 -> Not decided | G17: =$G$369 | H17: =$H$369 -> 0 | I17: =$I$369 -> -
B18: 12 | C18: 372 | D18: MC / COMPERE | E18: =COUNTA(F374:H374) -> 0 | F18: =$F$394 -> Not decided | G18: =$G$394 | H18: =$H$394 -> 0 | I18: =$I$394 -> -
B19: 13 | C19: 397 | D19: DJ / BAND | E19: =COUNTA(F399:H399) -> 0 | F19: =$F$422 -> Not decided | G19: =$G$422 | H19: =$H$422 -> 0 | I19: =$I$422 -> -
B20: 14 | C20: 425 | D20: TRANSPORT | E20: =COUNTA(F427:H427) -> 0 | F20: =$F$450 -> Not decided | G20: =$G$450 | H20: =$H$450 -> 0 | I20: =$I$450 -> -
B21: 15 | C21: 453 | D21: PRINTING / INVITATIONS | E21: =COUNTA(F455:H455) -> 0 | F21: =$F$477 -> Not decided | G21: =$G$477 | H21: =$H$477 -> 0 | I21: =$I$477 -> -
B22: 16 | C22: 480 | D22: SOUND, AV & LIGHTING | E22: =COUNTA(F482:H482) -> 0 | F22: =$F$505 -> Not decided | G22: =$G$505 | H22: =$H$505 -> 0 | I22: =$I$505 -> -
B25: 01 · VENUE / HOTEL | I25: back to index: row 5
B26: # | C26: Group | D26: What to ask / compare | E26: Why it matters - what to watch for | F26: OPTION A | G26: OPTION B | H26: OPTION C | I26: Your notes
D27: Vendor / company name
D28: Contact person
D29: Phone / WhatsApp
D30: Package or option quoted
D31: Total quoted (LKR)
D32: After negotiation (LKR)
D33: Deposit required (LKR)
D34: Met them / site visit done?
D35: Your rating out of 5
B36: QUESTIONS TO CONFIRM BEFORE YOU BOOK
B37: 1 | C37: MONEY | D37: Package rate per head for adults - and exactly what does it cover? | E37: The headline number is meaningless until you know what is inside it.
B38: 2 | C38: MONEY | D38: Minimum guaranteed guests you must pay for, even if fewer come | E38: You pay this whether they turn up or not. It sets your real floor price.
B39: 3 | C39: MONEY | D39: Rate for children, and up to what age is a child a child? | E39: Some hotels charge full price from age 6, others from 12.
B40: 4 | C40: MONEY | D40: Are service charge and taxes (VAT / SSCL / TDL) included or added on top? | E40: Adding these later can lift a quote by 25-30%.
B41: 5 | C41: MONEY | D41: Charge per extra hour beyond the agreed finish time | E41: Sri Lankan receptions run late. Agree this before, not at midnight.
B42: 6 | C42: MONEY | D42: Corkage per bottle - hard liquor, beer and wine separately | E42: Corkage can cost more than the alcohol itself.
B43: 7 | C43: MONEY | D43: Is there a minimum bar spend? | E43: A minimum can force you to buy drink you do not need.
B44: 8 | C44: MONEY | D44: Do vendors and crew count in the head count, and what is the crew meal rate? | E44: 20 crew at full guest rate is a large hidden line.
...

Sheet 06 Contributions
B2: FAMILY & COUPLE CONTRIBUTIONS
B3: Who has agreed to fund what, and how much has actually arrived. Nothing is assumed - fill this in to match your own family arrangement.
E5: TOTALS | G5: =SUM(G7:G60) -> 0 | H5: =SUM(H7:H60) -> 0 | I5: =SUM(I7:I60) -> 0
B6: ID | C6: Contributor | D6: Relationship | E6: Purpose / category | F6: Agreed on | G6: Agreed amount | H6: Received to date | I6: Still to come | J6: Last received on | K6: Notes
B7: C01 | C7: Groom's family | D7: Groom's parents | E7: General wedding fund | I7: =IF(G7="","",MAX(0,G7-H7))
B8: C02 | C8: Bride's family | D8: Bride's parents | E8: General wedding fund | I8: =IF(G8="","",MAX(0,G8-H8))
B9: C03 | C9: Couple - joint savings | D9: Bride & Groom | E9: General wedding fund | I9: =IF(G9="","",MAX(0,G9-H9))
B10: C04 | C10: Groom | D10: Groom | E10: Jewellery & rings | I10: =IF(G10="","",MAX(0,G10-H10))
B11: C05 | C11: Other | I11: =IF(G11="","",MAX(0,G11-H11))
I12: =IF(G12="","",MAX(0,G12-H12))
I13: =IF(G13="","",MAX(0,G13-H13))
I14: =IF(G14="","",MAX(0,G14-H14))
I15: =IF(G15="","",MAX(0,G15-H15))
I16: =IF(G16="","",MAX(0,G16-H16))
I17: =IF(G17="","",MAX(0,G17-H17))
I18: =IF(G18="","",MAX(0,G18-H18))
I19: =IF(G19="","",MAX(0,G19-H19))
I20: =IF(G20="","",MAX(0,G20-H20))
I21: =IF(G21="","",MAX(0,G21-H21))
I22: =IF(G22="","",MAX(0,G22-H22))
I23: =IF(G23="","",MAX(0,G23-H23))
... I60: =IF(G60="","",MAX(0,G60-H60))

Sheet 07 Tasks
B2: MASTER TASK LIST
B3: Due dates are formulas counted back from the wedding date - change the date on 01 START HERE and the whole plan re-dates itself. Sort or filter by Flag to see what is overdue.
D5: TASK SUMMARY | E5: ="Total: "&COUNTA(D7:D250) -> Total: 93 | G5: ="Done: "&COUNTIF(K7:K250,"Completed") -> Done: 1 | J5: ="Overdue: "&COUNTIF(L7:L250,"OVERDUE") -> Overdue: 0 | K5: ="This week: "&COUNTIF(L7:L250,"This week") -> This week: 1
B6: ID | C6: Category | D6: Task | E6: Owner | F6: Backup | G6: Priority | H6: Start date | I6: Due date | J6: Days left | K6: Status | L6: Flag | M6: Depends on | N6: Vendor | O6: Cost | P6: Payment needed? | Q6: Completed on | R6: Notes
B7: T001 | C7: Finance | D7: Agree the total wedding budget and who contributes what | E7: Couple | G7: Critical | I7: =WeddingDate-360 -> 46273 | J7: =IF($I7="","",$I7-TODAY()) -> 5 | K7: Not Started | L7: =IF($D7="","",IF($K7="Completed","Done",IF($K7="Cancelled","-",IF($I7="","No date",IF($I7<TODAY(),"OVERDUE",IF($I7=TODAY(),"TODAY",IF($I7<=TODAY()+7,"This week",IF($I7<=TODAY()+30,"This month","Upcoming")))))))) -> This week
B8: T002 | C8: Finance | D8: Open a dedicated wedding savings account | E8: Couple | G8: High | I8: =WeddingDate-350 -> 46283 | J8: =IF($I8="","",$I8-TODAY()) -> 15 | K8: Not Started | L8: =IF($D8="","",IF($K8="Completed","Done",IF($K8="Cancelled","-",IF($I8="","No date",IF($I8<TODAY(),"OVERDUE",IF($I8=TODAY(),"TODAY",IF($I8<=TODAY()+7,"This week",IF($I8<=TODAY()+30,"This month","Upcoming")))))))) -> This month
B9: T003 | C9: Venue | D9: Shortlist and visit 3-4 hotels / banquet halls | E9: Couple | G9: Critical | I9: =WeddingDate-345 -> 46288 | J9: =IF($I9="","",$I9-TODAY()) -> 20 | K9: Not Started | L9: =IF($D9="","",IF($K9="Completed","Done",IF($K9="Cancelled","-",IF($I9="","No date",IF($I9<TODAY(),"OVERDUE",IF($I9=TODAY(),"TODAY",IF($I9<=TODAY()+7,"This week",IF($I9<=TODAY()+30,"This month","Upcoming")))))))) -> This month
B10: T004 | C10: Venue | D10: Confirm the auspicious time (nekath) with the astrologer | E10: Groom's Family | G10: Critical | I10: =WeddingDate-340 -> 46293 | J10: =IF($I10="","",$I10-TODAY()) -> 25 | K10: Not Started | L10: =IF($D10="","",IF($K10="Completed","Done",IF($K10="Cancelled","-",IF($I10="","No date",IF($I10<TODAY(),"OVERDUE",IF($I10=TODAY(),"TODAY",IF($I10<=TODAY()+7,"This week",IF($I10<=TODAY()+30,"This month","Upcoming")))))))) -> This month
B11: T005 | C11: Venue | D11: Block the date and pay the venue booking deposit | E11: Couple | G11: Critical | I11: =WeddingDate-330 -> 46303 | J11: =IF($I11="","",$I11-TODAY()) -> 35 | K11: Not Started | L11: =IF($D11="","",IF($K11="Completed","Done",IF($K11="Cancelled","-",IF($I11="","No date",IF($I11<TODAY(),"OVERDUE",IF($I11=TODAY(),"TODAY",IF($I11<=TODAY()+7,"This week",IF($I11<=TODAY()+30,"This month","Upcoming")))))))) -> Upcoming
B12: T006 | C12: Guests & RSVP | D12: Agree the guest ceiling with both families | E12: Couple | G12: Critical | I12: =WeddingDate-330 -> 46303 | J12: =IF($I12="","",$I12-TODAY()) -> 35 | K12: Not Started | L12: =IF($D12="","",IF($K12="Completed","Done",IF($K12="Cancelled","-",IF($I12="","No date",IF($I12<TODAY(),"OVERDUE",IF($I12=TODAY(),"TODAY",IF($I12<=TODAY()+7,"This week",IF($I12<=TODAY()+30,"This month","Upcoming")))))))) -> Upcoming
B13: T007 | C13: Venue | D13: Sign the venue contract and read the cancellation clause | E13: Couple | G13: Critical | I13: =WeddingDate-320 -> 46313 | J13: =IF($I13="","",$I13-TODAY()) -> 45 | K13: Not Started | L13: =IF($D13="","",IF($K13="Completed","Done",IF($K13="Cancelled","-",IF($I13="","No date",IF($I13<TODAY(),"OVERDUE",IF($I13=TODAY(),"TODAY",IF($I13<=TODAY()+7,"This week",IF($I13<=TODAY()+30,"This month","Upcoming")))))))) -> Upcoming
B14: T008 | C14: Photography | D14: Shortlist photographers and review full wedding albums | E14: Couple | G14: High | I14: =WeddingDate-300 -> 46333 | J14: =IF($I14="","",$I14-TODAY()) -> 65 | K14: Not Started | L14: =IF($D14="","",IF($K14="Completed","Done",IF($K14="Cancelled","-",IF($I14="","No date",IF($I14<TODAY(),"OVERDUE",IF($I14=TODAY(),"TODAY",IF($I14<=TODAY()+7,"This week",IF($I14<=TODAY()+30,"This month","Upcoming")))))))) -> Upcoming
B15: T009 | C15: Videography | D15: Shortlist videographers and watch full highlight films | E15: Couple | G15: High | I15: =WeddingDate-300 -> 46333 | J15: =IF($I15="","",$I15-TODAY()) -> 65 | K15: Not Started | L15: =IF($D15="","",IF($K15="Completed","Done",IF($K15="Cancelled","-",IF($I15="","No date",IF($I15<TODAY(),"OVERDUE",IF($I15=TODAY(),"TODAY",IF($I15<=TODAY()+7,"This week",IF($I15<=TODAY()+30,"This month","Upcoming")))))))) -> Upcoming
B16: T010 | C16: Photography | D16: Book the photographer and pay the deposit | E16: Couple | G16: Critical | I16: =WeddingDate-285 -> 46348 | J16: =IF($I16="","",$I16-TODAY()) -> 80 | K16: Not Started | L16: =IF($D16="","",IF($K16="Completed","Done",IF($K16="Cancelled","-",IF($I16="","No date",IF($I16<TODAY(),"OVERDUE",IF($I16=TODAY(),"TODAY",IF($I16<=TODAY()+7,"This week",IF($I16<=TODAY()+30,"This month","Upcoming")))))))) -> Upcoming
